Workbook
Name AsOfDate: 'Instructions & Assumptions'!$B$4
Name ATNW_Active: 'Instructions & Assumptions'!$B$28
Name Bajaj_TL_Maturity: 'Instructions & Assumptions'!$B$52
Name Bajaj_TL_PrincOS: 'Repayment Schedule'!$D$63
Name Bajaj_TL_PrincRepaid: 'Repayment Schedule'!$C$63
Name Bajaj_TL_SNo: 'Instructions & Assumptions'!$B$57
Name BFRR_Bajaj: 'Instructions & Assumptions'!$B$16
Name BMK_12M_MCLR_SIB: 'Instructions & Assumptions'!$C$18
Name BMK_1Y_MCLR_RBL: 'Instructions & Assumptions'!$C$15
Name BMK_3M_MCLR_YBL: 'Instructions & Assumptions'!$C$16
Name BMK_3M_TBILL: 'Instructions & Assumptions'!$C$13
Name BMK_6M_IMCLR_ICICI: 'Instructions & Assumptions'!$C$17
Name BMK_BFRR: 'Instructions & Assumptions'!$C$19
Name BMK_FD_RATE: 'Instructions & Assumptions'!$C$21
Name BMK_REPO: 'Instructions & Assumptions'!$C$14
Name BMK_TERM_SOFR: 'Instructions & Assumptions'!$C$20
Name Bucket1_DebtTotal: 'Lender Summary'!$D$10
Name Bucket1_Interest: 'Interest Schedule'!$I$40
Name Bucket1_TL_Total: 'Lender Summary'!$B$10
Name CA_Active: 'Instructions & Assumptions'!$B$29
Name CL_Active: 'Instructions & Assumptions'!$B$30
Name CovenantBreached: 'Covenant Tracker'!$B$33
Name CovenantCompliant: 'Covenant Tracker'!$B$31
Name CovenantCount: 'Covenant Tracker'!$B$30
Name CovenantNearBreach: 'Covenant Tracker'!$B$32
Name CovenantPending: 'Covenant Tracker'!$B$34
Name DaysInYear: 'Instructions & Assumptions'!$B$7
Name EBITDA_Active: 'Instructions & Assumptions'!$B$24
Name FA_Active: 'Instructions & Assumptions'!$B$33
Name FBMainsTotal: 'Lender Summary'!$B$10
Name FD_Rate_RBL: 'Instructions & Assumptions'!$B$20
Name FDBackedTotal: 'Lender Summary'!$D$30
Name FIN_ATNW: 'Instructions & Assumptions'!$C$29
Name FIN_CA: 'Instructions & Assumptions'!$C$30
Name FIN_CL: 'Instructions & Assumptions'!$C$31
Name FIN_EBITDA: 'Instructions & Assumptions'!$C$25
Name FIN_FA_NET: 'Instructions & Assumptions'!$C$34
Name FIN_INT_EXP: 'Instructions & Assumptions'!$C$33
Name FIN_PRINC_REP: 'Instructions & Assumptions'!$C$38
Name FIN_PROM_SHARE: 'Instructions & Assumptions'!$C$37
Name FIN_RATING: 'Instructions & Assumptions'!$C$36
Name FIN_SCHED_REPAY: 'Instructions & Assumptions'!$C$40
Name FIN_SEC_DEBT: 'Instructions & Assumptions'!$C$35
Name FIN_TAX_PAID: 'Instructions & Assumptions'!$C$39
Name FIN_TERM_DEBT: 'Instructions & Assumptions'!$C$27
Name FIN_TNW: 'Instructions & Assumptions'!$C$28
Name FIN_TOL: 'Instructions & Assumptions'!$C$32
Name FIN_TOTAL_DEBT: 'Instructions & Assumptions'!$C$26
Name FinancialBasis: 'Instructions & Assumptions'!$C$10
Name FinBasis: 'Instructions & Assumptions'!$B$8
Name FX_USD_INR: 'Instructions & Assumptions'!$B$5
Name HedgeNotionalTotal: 'Lender Summary'!$C$37
Name IMCLR_ICICI_6M: 'Instructions & Assumptions'!$B$14
Name IntExp_Active: 'Instructions & Assumptions'!$B$32
Name LenderFilter: Dashboard!$H$5
Name MCLR_RBL_1Y: 'Instructions & Assumptions'!$B$12
Name MCLR_SIB_12M: 'Instructions & Assumptions'!$B$15
Name MCLR_YBL_3M: 'Instructions & Assumptions'!$B$13
Name NFBContingent: 'Lender Summary'!$D$20
Name NFBMainsTotal: 'Lender Summary'!$C$10

Sheet Cover Page
A1: JINDAL COKE LIMITED
A2: Debt Monitoring Model
A4: ="As of: " & TEXT(AsOfDate,"dd-mmm-yyyy") -> As of: 31-Mar-2026
B6: Active Lenders | D6: {=ROUND(SUMPRODUCT(1/COUNTIF('Facility Master'!B5:B38,'Facility Master'!B5:B38&"")),0)} -> 5
B7: Total Facility Lines (incl. sub-limits) | D7: =COUNTIF('Facility Master'!A5:A38,">0") -> 34
B8: Sanctioned Debt (₹ Cr) | D8: =SanctionedDebt -> 1320.7
B9: NFB Contingent (₹ Cr) | D9: =NFBContingent -> 815
B10: As-of Date | D10: =AsOfDate -> 46112
B11: FD-Backed Separate Lines (₹ Cr) | D11: =FDBackedTotal -> 100
B12: Prepared by | D12: Divyanshu Vatsa · Treasury
A13: WORKBOOK TAB GUIDE
A14: Tab | C14: Description
A15: Cover Page | C15: This page — model summary and tab map.
A16: Notes | C16: Methodology and reading guide for first-time viewers.
A17: Dashboard | C17: Senior management one-pager — KPI tiles, covenant status, lender concentration, narratives.
A18: Instructions & Assumptions | C18: Core inputs, benchmark rates, financial assumptions, sanction-letter caps.
A19: Facility Master | C19: Single source of truth — all 34 facilities with structural, pricing, and tenor data.
A20: Lender Summary | C20: Three-bucket aggregation: Sanctioned Debt, NFB Contingent, Separate Lines, by lender.
A21: Working Capital Facilities | C21: Operational view of all WC fund-based lines with cap-basis aggregation.
A22: Term Loans | C22: Detailed view of the three term loans with parameters and totals.
A23: Non-Fund Based Facilities | C23: LCs, SBLCs, BGs, Capex LCs, and hedge notional facilities.
A24: Repayment Schedule | C24: 53-period quarterly schedule for the three TLs and consolidated.
A25: Interest Schedule | C25: Annual interest and commission cost by facility; weighted-average debt cost.
... A32: Validation Engine | C32: 51-check internal validation engine — PPT-referenced Master Status (PASS/FAIL/Critical).

Sheet Notes
A1: MODEL NOTES & METHODOLOGY — Path B (Optimized)
A2: Prepared by Divyanshu Vatsa · Treasury · Last revised: 8 May 2026
A4: 1. BUCKET DECISION TREE
A5: Q1. | B5: Is the facility a sub-limit of another facility already in the model? Either (a) labelled in the sanction letter, or (b) sharing a binding cap with an umbrella facility such that drawing it reduces the umbrella's available capacity. If YES → BUCKET 0 (excluded from totals).
A6: Q2. | B6: Is the facility FD-backed (collateralised by 100% Fixed Deposit)? If YES → BUCKET 3 (Separate Lines). Currently only RBL FDOD ₹100 Cr.
A7: Q3. | B7: Is the facility fund-based (FB, FB-Term, FB-FCY)? If YES → BUCKET 1 (FB Mains). Currently 4 facilities: YBL TL ₹320.7 + Bajaj TL ₹150 + ICICI CC ₹50 + RBL TL Main ₹200 = ₹720.7 Cr.
A8: Q4. | B8: Is the facility non-fund-based (NFB)? If YES → BUCKET 2 (NFB Mains). Currently 4 facilities: YBL LC ₹200 + ICICI LC ₹150 + SIB LC ₹150 + RBL LC Main ₹100 = ₹600 Cr.
A9: Memo. | B9: Hedge notional limits (RBL LER ₹20 + SIB Forward ₹3) are derivative caps, not credit facilities. Tracked in Lender Summary Memo line, not in any bucket.
A11: 2. KPI DEFINITIONS
A12: • | B12: Sanctioned Debt: = Bucket 1 + Bucket 2 = ₹1,320.7 Cr. Sum of all FB and NFB main parent facilities at sanction face value, excluding FD-backed lines. Industry-standard 'total credit sanctioned at parent level' view used in CRILC reporting, rating agency analyses, and bank credit memos. Distinct from drawn debt. Reconciles to sanction-letter caps: YBL TL 320.7 + YBL LC 200 + Bajaj TL 150 + ICICI Total 200 + SIB LC 150 + RBL TL 200 + RBL LC 100 = 1,320.7.
A13: • | B13: FB Economic Debt: = Bucket 1 alone = ₹720.7 Cr. The fund-based parent facilities at sanction face. Used as cost basis for weighted-average debt cost calculation (interest sits only on FB facilities).
A14: • | B14: NFB Mains: = Bucket 2 alone = ₹600 Cr. Pure NFB parent facilities, before adding sub-limit overlays.
A15: • | B15: NFB Contingent: = Bucket 2 + NFB sub-limits whose parent is a FB Main = ₹815 Cr. The two FB-Main NFB sub-limits counted are RBL SBLC for Buyer's Credit ₹190 Cr and RBL Capex LC ₹25 Cr (both sub of TL Main ₹200). Both create distinct third-party contingent exposure even though they consume TL Main capacity. The Lender Summary Bucket 2 column shows pure NFB Mains; the NFB Contingent KPI adds the in-FB-umbrella contingents.
A16: • | B16: FD-Backed (Separate Lines): = Bucket 3 = ₹100 Cr. RBL FDOD only — self-collateralised by 100% FD; explicitly excluded from RBL's ₹300 Cr Overall Borrower exposure cap per 31-Dec-2025 letter.
A17: • | B17: Hedge Notional (Memo): = ₹23 Cr (RBL LER 20 + SIB Forward 3). Derivative limits, not credit facilities. Out of all buckets; informational only.
A19: 3. SANCTION LETTER SOURCES
A20: • | B20: YES Bank: TL ₹320.7 Cr per Sanction Letter dated 16-Dec-2024 (Ref YBL/DEL/FI/1500/2024-25); pricing addendum 28-Mar-2025 changed spread T-Bill 3M + 2.45% → +2.52%. WC umbrella ₹200 Cr cap (incl ₹25 Cr treasury) per latest Renewal cum Addendum dated 19-Mar-2026 (Ref YBL/DEL/LC/FI/06790/03/2026). LC parent ₹200 Cr per original 9-May-2023 letter; Financial BG/SBLC ₹200 sub of LC; PIF ₹100, WCDL ₹50, CC ₹25 share the ₹200 WC cap → all sub-limits.
A21: • | B21: RBL Bank: Three Main Limits per 31-Dec-2025 Renewal cum Modification letter (Ref CAD/DEL/1093/2025-26): LC Main ₹100, TL Main ₹200, FDOD ₹100. Overall Borrower exposure capped ₹300 Cr (excl FD). Sub-limits explicitly labelled in letter: BG ₹25, PID ₹100, SBLC ₹100, LCBD ₹100, CC ₹100, WCDL ₹100, LER ₹20 (all sub of LC); SBLC for BC ₹190, Capex LC ₹25 (sub of TL); LC backed by FD ₹50 (sub of FDOD). Earlier letters dated 13-Mar-2025 (BC WC USD 11M / ₹100 Cr) and 27-Mar-2025 (BC CAPEX USD 20M / ₹172 Cr) consolidated into 31-Dec-2025 structure: 'Extension of availability period till December 2026 for the conversion o/s SBLCs/Buyers Credit to term loan' — therefore treated as sub-limits of TL Main.
A22: • | B22: Bajaj Finance: TL ₹150 Cr per 18-Aug-2025 sole letter. Pricing 8.60% (BFRR 8.50% + 10 bps). 8-yr tenor incl 12-mo moratorium. 28 quarterly instalments. 1st pari-passu on FA at Khurunti Coke Plant; MSC 1.25x.
A23: • | B23: ICICI Bank: FB ₹50 (CC, with WCDL ₹50 as interchangeable sub-limit) + NFB ₹150 (LC parent, with SBLC ₹150 + BG-Performance ₹25 + BG-Financial ₹5 nested inside) per CAL dated 16-Sep-2025 (issued 31-Oct-2025) and Addendum 11-Nov-2025. Total A+B = ₹200 Cr per Annexure I. LC to JSL Global Commodities Pte Ltd capped INR 25 Cr.
A24: • | B24: South Indian Bank: LC ₹150 Cr cap per 21-Jun-2025 Renewal letter; cap explicit: 'Total LC limit (including Capex LC) shall not exceed Rs.150.0 Crores'. Capex LC ₹50 → shared-cap sub-limit of LC. SBLC ₹150 (sub of LC), CCOL ₹50 (sub of LC), WCDL ₹50 (sub of CCOL). Forward Contract ₹3 Cr → hedge notional memo.
A26: 4. KEY TREATMENT DECISIONS
A27: • | B27: RBL Term Loan repayment schedule excluded from quarterly schedule. Drawdown pending — existing BC instruments converting to TL by Dec-2026 per latest letter. Sanction face ₹200 Cr remains in Bucket 1 / Sanctioned Debt; only the repayment schedule defers until drawdown completes.
A28: • | B28: RBL BC GIFT WC ₹100 Cr (per 13-Mar-2025 letter) and BC CAPEX ₹172 Cr (per 27-Mar-2025 letter) are superseded by the 31-Dec-2025 consolidated structure. Both reclassified to Bucket 0 (sub-limits of TL Main). Avoids ~₹272 Cr of double-counting that existed in prior version.
A29: • | B29: YBL PIF, WCDL, CC, BG/SBLC and Treasury limits all share the ₹200 Cr WC umbrella cap. Reclassified to Bucket 0 (shared-cap sub-limits of LC umbrella). LC ₹200 alone represents the umbrella in Bucket 2.
A30: • | B30: SIB Capex LC ₹50 Cr shares ₹150 Cr cap with main LC per letter wording. Reclassified to Bucket 0. SIB LC ₹150 represents the umbrella in Bucket 2.
A31: • | B31: RBL SBLC for BC ₹190 (sub of TL) and RBL Capex LC ₹25 (sub of TL) are NFB sub-limits of an FB-Main parent. Sit in Bucket 0 for sub-limit deduplication purposes, but flagged via 'NFB Contingent Flag' column AG in Facility Master to surface in NFB Contingent KPI (₹815 = Bucket 2 ₹600 + these two ₹215).
A32: • | B32: Hedge notional limits (RBL LER ₹20 sub of LC, SIB Forward ₹3 standalone) excluded from all buckets. LER → Bucket 0 (Q1 hits before Q2 since LER is sub-of-LC). SIB Forward → no parent, but it's a derivative cap not credit. Tracked in Memo section of Lender Summary.
A34: 5. WORKBOOK ARCHITECTURE
A35: • | B35: Facility Master is the single source of truth. All other sheets aggregate via SUMIFS on FM columns.
A36: • | B36: Named ranges (Excel Name Manager): SanctionedDebt, NFBContingent, FDBackedTotal, FBMainsTotal, NFBMainsTotal, HedgeNotionalTotal — point to Lender Summary anchor cells. Use these in formulas instead of cell references for portability.
A37: • | B37: NFB Contingent computed via column AG flag in Facility Master (TRUE for facilities contributing to NFB Contingent KPI). Lender Summary aggregates via SUMIFS on this flag plus H=2.
A38: • | B38: Repayment Schedule consolidated columns S-V (Total Prin, Total Int, Total DS, Combined O/S) sum YBL + Bajaj only; RBL excluded. Dashboard's 'Term Loan Maturity Profile' reads from these consolidated columns and inherits the exclusion.
A39: • | B39: Validation Engine has 51 checks (VVE-01 through VVE-51). Master Status at row 69 shows ✓ PASS only when zero critical fails.

Sheet Dashboard
A1: JCL DEBT MONITORING DASHBOARD
A2: ="As of: " & TEXT(AsOfDate,"dd-mmm-yyyy") & " • Financial Basis: " & FinBasis & " • All figures in INR Crores" -> As of: 31-Mar-2026 • Financial Basis: Projected • All figures in INR Crores
A4: Sanctioned Debt (₹ Cr) | D4: FB Mains — Bucket 1 (₹ Cr) | G4: NFB Mains — Bucket 2 (₹ Cr) | J4: NFB Contingent (₹ Cr)
A5: =SanctionedDebt -> 1320.7 | D5: =FBMainsTotal -> 720.7 | G5: =NFBMainsTotal -> 600 | J5: =NFBContingent -> 815
A6: B1 + B2; main parents only | D6: TLs + ICICI CC (parent FB) | G6: Parent NFB at all 4 lenders | J6: B2 + NFB sub of FB-Main
A8: FD-Backed Lines (₹ Cr) | D8: Bucket 1 Outstanding (₹ Cr) | G8: Wt. Avg Cost of FB Economic Debt | J8: Annual Interest + Comm.
A9: =FDBackedTotal -> 100 | D9: =IFERROR(SUMIFS('Facility Master'!M:M,'Facility Master'!H:H,1),0) -> 495.9612 | G9: =WtAvgDebtCost -> 0.080780538 | J9: =TotalIntComm -> 49.039012
A10: Self-collateralised; excl. RBL ₹300 cap | D10: Drawn Bucket-1 (effective O/S) | G10: Bucket 1 (FB) cost basis only — interest accrues on FB | J10: Total run-rate (interest + commission)
A12: Active Facilities | D12: TL Earliest Maturity | G12: TL Farthest Maturity | J12: Avg Debt Utilisation
A13: =IFERROR(34-COUNTIF('Facility Master'!F:F,TRUE()),0) -> 10 | D13: =IFERROR(_xlfn.MINIFS('Facility Master'!Z:Z,'Facility Master'!D:D,"FB-Term",'Facility Master'!H:H,1),"") -> 47208 | G13: =IFERROR(_xlfn.MAXIFS('Facility Master'!Z:Z,'Facility Master'!D:D,"FB-Term",'Facility Master'!H:H,1),"") -> 49948 | J13: =IFERROR(SUMIFS('Facility Master'!M:M,'Facility Master'!H:H,1)/SUMIFS('Facility Master'!K:K,'Facility Master'!H:H,1),0) -> 0.68816595
A14: Excludes sub-limits | D14: First TL maturing | G14: Last TL maturing | J14: Eff. outstanding / sanctioned (Bucket 1)
A16: Covenant Compliance
A17: Total | B17: Compliant | C17: Near Breach | D17: Breached | E17: Pending | F17: Compliance %
A18: =CovenantCount -> 24 | B18: =CovenantCompliant -> 24 | C18: =CovenantNearBreach -> 0 | D18: =CovenantBreached -> 0 | E18: =CovenantPending -> 0 | F18: =PortfolioCompliancePct -> 1
A20: ="Portfolio Compliance: " & TEXT(PortfolioCompliancePct,"0.0%") & " (" & CovenantCompliant & " of " & CovenantCount & " covenants Compliant). " & CovenantNearBreach & " Near Breach. " & CovenantBreached & " Breached. " & CovenantPending & " Pending Input." -> Portfolio Compliance: 100.0% (24 of 24 covenants Compliant). 0 Near Breach. 0 Breached. 0 Pending Input.
A23: Lender Concentration — Sanctioned Debt
A24: Lender | B24: Sanctioned Debt (₹ Cr) | C24: % of Sanctioned Debt | L24: Relative Share ▶
A25: YES Bank | B25: ='Lender Summary'!D6 -> 520.7 | C25: =IFERROR(B25/SanctionedDebt,0) -> 0.39426062 | E25: =REPT("█", ROUND(C25*40,0)) -> ████████████████
A26: RBL Bank | B26: ='Lender Summary'!D5 -> 300 | C26: =IFERROR(B26/SanctionedDebt,0) -> 0.22715227 | E26: =REPT("█", ROUND(C26*40,0)) -> █████████
A27: ICICI Bank | B27: ='Lender Summary'!D8 -> 200 | C27: =IFERROR(B27/SanctionedDebt,0) -> 0.15143485 | E27: =REPT("█", ROUND(C27*40,0)) -> ██████
A28: Bajaj Finance | B28: ='Lender Summary'!D7 -> 150 | C28: =IFERROR(B28/SanctionedDebt,0) -> 0.11357613 | E28: =REPT("█", ROUND(C28*40,0)) -> █████
A29: South Indian Bank | B29: ='Lender Summary'!D9 -> 150 | C29: =IFERROR(B29/SanctionedDebt,0) -> 0.11357613 | E29: =REPT("█", ROUND(C29*40,0)) -> █████
A32: Term Loan Maturity Profile by Fiscal Year
A33: FY | B33: Period Start | C33: Period End | D33: Total Principal Due (₹ Cr) | E33: Cumulative | F33: Annual Bar ▶
A34: FY24 | B34: =DATE(2023,4,1) -> 45017 | C34: =DATE(2024,3,31) -> 45382 | D34: =IFERROR(SUMIFS('Repayment Schedule'!S:S,'Repayment Schedule'!B:B,">="&B34,'Repayment Schedule'!B:B,"<="&C34),0) -> 0 | E34: =D34 -> 0 | F34: =IFERROR(REPT("█",ROUND(D34/48.72*30,0)),"")
A35: FY25 | B35: =DATE(2024,4,1) -> 45383 | C35: =DATE(2025,3,31) -> 45747 | D35: =IFERROR(SUMIFS('Repayment Schedule'!S:S,'Repayment Schedule'!B:B,">="&B35,'Repayment Schedule'!B:B,"<="&C35),0) -> 0 | E35: =E34+D35 -> 0 | F35: =IFERROR(REPT("█",ROUND(D35/48.72*30,0)),"")
A36: FY26 | B36: =DATE(2025,4,1) -> 45748 | C36: =DATE(2026,3,31) -> 46112 | D36: =IFERROR(SUMIFS('Repayment Schedule'!S:S,'Repayment Schedule'!B:B,">="&B36,'Repayment Schedule'!B:B,"<="&C36),0) -> 24.7388 | E36: =E35+D36 -> 24.7388 | F36: =IFERROR(REPT("█",ROUND(D36/48.72*30,0)),"") -> ███████████████
A37: FY27 | B37: =DATE(2026,4,1) -> 46113 | C37: =DATE(2027,3,31) -> 46477 | D37: =IFERROR(SUMIFS('Repayment Schedule'!S:S,'Repayment Schedule'!B:B,">="&B37,'Repayment Schedule'!B:B,"<="&C37),0) -> 35.453086 | E37: =E36+D37 -> 60.191886 | F37: =IFERROR(REPT("█",ROUND(D37/48.72*30,0)),"") -> ██████████████████████
A38: FY28 | B38: =DATE(2027,4,1) -> 46478 | C38: =DATE(2028,3,31) -> 46843 | D38: =IFERROR(SUMIFS('Repayment Schedule'!S:S,'Repayment Schedule'!B:B,">="&B38,'Repayment Schedule'!B:B,"<="&C38),0) -> 46.167372 | E38: =E37+D38 -> 106.35926 | F38: =IFERROR(REPT("█",ROUND(D38/48.72*30,0)),"") -> ████████████████████████████
A39: FY29 | B39: =DATE(2028,4,1) -> 46844 | C39: =DATE(2029,3,31) -> 47208 | D39: =IFERROR(SUMIFS('Repayment Schedule'!S:S,'Repayment Schedule'!B:B,">="&B39,'Repayment Schedule'!B:B,"<="&C39),0) -> 46.427772 | E39: =E38+D39 -> 152.78703 | F39: =IFERROR(REPT("█",ROUND(D39/48.72*30,0)),"") -> █████████████████████████████
A40: FY30 | B40: =DATE(2029,4,1) -> 47209 | C40: =DATE(2030,3,31) -> 47573 | D40: =IFERROR(SUMIFS('Repayment Schedule'!S:S,'Repayment Schedule'!B:B,">="&B40,'Repayment Schedule'!B:B,"<="&C40),0) -> 47.956972 | E40: =E39+D40 -> 200.744 | F40: =IFERROR(REPT("█",ROUND(D40/48.72*30,0)),"") -> ██████████████████████████████
A41: FY31 | B41: =DATE(2030,4,1) -> 47574 | C41: =DATE(2031,3,31) -> 47938 | D41: =IFERROR(SUMIFS('Repayment Schedule'!S:S,'Repayment Schedule'!B:B,">="&B41,'Repayment Schedule'!B:B,"<="&C41),0) -> 50.317372 | E41: =E40+D41 -> 251.06137 | F41: =IFERROR(REPT("█",ROUND(D41/48.72*30,0)),"") -> ███████████████████████████████
A42: FY32 | B42: =DATE(2031,4,1) -> 47939 | C42: =DATE(2032,3,31) -> 48304 | D42: =IFERROR(SUMIFS('Repayment Schedule'!S:S,'Repayment Schedule'!B:B,">="&B42,'Repayment Schedule'!B:B,"<="&C42),0) -> 52.400572 | E42: =E41+D42 -> 303.46194 | F42: =IFERROR(REPT("█",ROUND(D42/48.72*30,0)),"") -> ████████████████████████████████
A43: FY33 | B43: =DATE(2032,4,1) -> 48305 | C43: =DATE(2033,3,31) -> 48669 | D43: =IFERROR(SUMIFS('Repayment Schedule'!S:S,'Repayment Schedule'!B:B,">="&B43,'Repayment Schedule'!B:B,"<="&C43),0) -> 52.400572 | E43: =E42+D43 -> 355.86252 | F43: =IFERROR(REPT("█",ROUND(D43/48.72*30,0)),"") -> ████████████████████████████████
A44: FY34 | B44: =DATE(2033,4,1) -> 48670 | C44: =DATE(2034,3,31) -> 49034 | D44: =IFERROR(SUMIFS('Repayment Schedule'!S:S,'Repayment Schedule'!B:B,">="&B44,'Repayment Schedule'!B:B,"<="&C44),0) -> 41.686285 | E44: =E43+D44 -> 397.5488 | F44: =IFERROR(REPT("█",ROUND(D44/48.72*30,0)),"") -> ██████████████████████████
A45: FY35 | B45: =DATE(2034,4,1) -> 49035 | C45: =DATE(2035,3,31) -> 49399 | D45: =IFERROR(SUMIFS('Repayment Schedule'!S:S,'Repayment Schedule'!B:B,">="&B45,'Repayment Schedule'!B:B,"<="&C45),0) -> 32.2228 | E45: =E44+D45 -> 429.7716 | F45: =IFERROR(REPT("█",ROUND(D45/48.72*30,0)),"") -> ████████████████████
A46: FY36 | B46: =DATE(2035,4,1) -> 49400 | C46: =DATE(2036,3,31) -> 49765 | D46: =IFERROR(SUMIFS('Repayment Schedule'!S:S,'Repayment Schedule'!B:B,">="&B46,'Repayment Schedule'!B:B,"<="&C46),0) -> 36.112 | E46: =E45+D46 -> 465.8836 | F46: =IFERROR(REPT("█",ROUND(D46/48.72*30,0)),"") -> ██████████████████████
A47: FY37 | B47: =DATE(2036,4,1) -> 49766 | C47: =DATE(2037,3,31) -> 50130 | D47: =IFERROR(SUMIFS('Repayment Schedule'!S:S,'Repayment Schedule'!B:B,">="&B47,'Repayment Schedule'!B:B,"<="&C47),0) -> 4.8164 | E47: =E46+D47 -> 470.7 | F47: =IFERROR(REPT("█",ROUND(D47/48.72*30,0)),"") -> ███
A50: Facility Type Mix
A51: Bucket | B51: Amount (₹ Cr) | C51: % of Sanctioned | D51: Visual
...

Sheet Instructions & Assumptions
A1: INSTRUCTIONS & ASSUMPTIONS
A3: A. Core Model Parameters | B3: Value | C3: Unit | D3: Notes
A4: As-of Date | B4: =DATE(2026,3,31) -> 46112 | C4: date | D4: Drives remaining-tenor and covenant-period calculations.
A5: USD / INR FX Rate | B5: 92.98 | C5: ₹/USD | D5: Drives INR equivalents of USD-denominated facilities subject to sanction-letter caps.
A6: Use Full Utilisation = Sanctioned? | B6: =TRUE() -> TRUE | C6: TRUE/FALSE | D6: If TRUE, Effective Outstanding = Sanctioned. If FALSE, uses Current Outstanding from Facility Master Col N.
A7: Days in Year | B7: 365 | C7: days | D7: Day-count convention for interest computation.
A8: Financial Basis (Actual / Projected) | B8: Projected | C8: Basis | D8: Toggle drives Section C 'Active' column which feeds the Covenant Tracker.
A11: B. Benchmark Rates | B11: Current Rate | D11: Source / Notes
A12: 1Y MCLR (RBL Bank) | B12: 0.09 | D12: RBL Bank 1Y MCLR (Apr-2026).
A13: 3M MCLR (YBL) | B13: 0.09 | D13: YES Bank 3M MCLR (Apr-2026).
A14: 6M I-MCLR (ICICI) | B14: 0.083 | D14: ICICI 6M I-MCLR effective 22-Jan-2026.
A15: 12M MCLR (SIB) | B15: 0.0975 | D15: SIB 12M MCLR per sanction letter dated 21-Jun-2025.
A16: Bajaj Floating Reference Rate (BFRR) | B16: 0.085 | D16: Per Bajaj sanction letter dated 18-Aug-2025.
A17: Term SOFR (USD) 3M | B17: 0.043 | D17: Term SOFR 3M, Apr-2026.
A18: 3M T-Bill | B18: 0.0518 | D18: India 3M T-Bill yield, Apr-2026.
A19: Repo Rate | B19: 0.0525 | D19: RBI Policy Repo Rate, Apr-2026.
A20: FD rate (RBL FDOD) | B20: 0.07 | D20: Customer-specific FD rate backing the RBL FDOD facility.
A22: C. Management Financials (INR Cr) | B22: Active (toggle) | C22: FY24A | D22: FY26E
A24: EBITDA | B24: {=IFERROR(IF(FinBasis="Actual",C24,D24),0)} -> 383.96 | C24: 173.37 | D24: 383.96
A25: Total Debt (Gross) | B25: {=IFERROR(IF(FinBasis="Actual",C25,D25),0)} -> 613.03 | C25: 471.82 | D25: 613.03
A26: Term Debt | B26: {=IFERROR(IF(FinBasis="Actual",C26,D26),0)} -> 431.28 | C26: 324.01 | D26: 431.28
A27: Tangible Net Worth (TNW) | B27: {=IFERROR(IF(FinBasis="Actual",C27,D27),0)} -> 740.13 | C27: 720.11 | D27: 740.13
A28: Adjusted TNW (ATNW) | B28: {=IFERROR(IF(FinBasis="Actual",C28,D28),0)} -> 720.76 | C28: 588.29 | D28: 720.76
A29: Current Assets | B29: {=IFERROR(IF(FinBasis="Actual",C29,D29),0)} -> 755.02 | C29: 711.3 | D29: 755.02
A30: Current Liabilities | B30: {=IFERROR(IF(FinBasis="Actual",C30,D30),0)} -> 544.79 | C30: 513.82 | D30: 544.79
A31: Total Outside Liabilities (TOL) | B31: {=IFERROR(IF(FinBasis="Actual",C31,D31),0)} -> 1143.49 | C31: 1143.77 | D31: 1143.49
A32: Interest Expense (TTM) | B32: {=IFERROR(IF(FinBasis="Actual",C32,D32),0)} -> 49.08 | C32: 39.87 | D32: 49.08
A33: Fixed Assets (net block) | B33: {=IFERROR(IF(FinBasis="Actual",C33,D33),0)} -> 937.69 | C33: 449.34 | D33: 937.69
A34: Secured Debt (outstanding) | B34: {=IFERROR(IF(FinBasis="Actual",C34,D34),0)} -> 431.28 | C34: 324.01 | D34: 431.28
A35: External Rating | B35: {=IFERROR(IF(FinBasis="Actual",C35,D35),0)} -> CARE A+; Stable / A1 | C35: CARE A+; Stable / A1 | D35: CARE A+; Stable / A1
A36: Promoter Shareholding % | B36: {=IFERROR(IF(FinBasis="Actual",C36,D36),0)} -> 1 | C36: 1 | D36: 1
A37: Principal Repayment (TTM) | B37: {=IFERROR(IF(FinBasis="Actual",C37,D37),0)} -> 170.07 | C37: 18.76 | D37: 170.07
A38: Tax Paid (TTM) | B38: {=IFERROR(IF(FinBasis="Actual",C38,D38),0)} -> 69.36 | C38: 0 | D38: 69.36
A39: Scheduled TL Repayment (next 12M) | B39: {=IFERROR(IF(FinBasis="Actual",C39,D39),0)} -> 41.09 | C39: 0 | D39: 41.09
A41: D. Sanction-Letter Binding Caps (INR Cr) | B41: Value
A42: RBL — INR WC Umbrella Cap | B42: 100
A43: RBL — GIFT City BC Working Capital Cap | B43: 100
A44: RBL — GIFT City BC CAPEX Cap | B44: 172
A45: ICICI — Fund-Based Cap | B45: 50
A46: SIB — CCOL Cap | B46: 50
...

Sheet Facility Master
A1: FACILITY MASTER
A3: Identification | G3: Flags | I3: Financial Structure | P3: Pricing | U3: Repayment | Y3: Dates | AE3: Reference & Notes
A4: S.No | B4: Lender | C4: Facility | D4: Category | E4: Nature | F4: Sub-Limit Flag | G4: FD-Backed | H4: Bucket | I4: Currency | J4: Sanc Orig Ccy | K4: Sanc INR Cr | L4: Current O/S | M4: Eff Current O/S | N4: Util % | O4: Headroom | P4: Benchmark | Q4: Spread | R4: Eff Rate p.a. | S4: Rate Type | T4: Moratorium Mths | U4: Rep Frequency | V4: Tenor Mths | W4: No of Instalments | X4: Drawdown Date | Y4: Rep Start Date | Z4: Maturity Date | AA4: Sanction Date | AB4: Validity Date | AC4: Purpose | AD4: Security Summary | AE4: Sanction Reference | AF4: Remarks | AG4: NFB Contingent Flag
A5: 1 | B5: RBL Bank | C5: Letter of Credit - Main Limit | D5: NFB | E5: Revolving | F5: =FALSE() -> FALSE | G5: =FALSE() -> FALSE | H5: 2 | I5: INR | J5: 100 | K5: =IFERROR(J5,0) -> 100 | M5: =IFERROR(IF(D5="FB-Term",IF(A5=RBL_TL_SNo,RBL_TL_PrincOS,IF(A5=YBL_TL_SNo,YBL_TL_PrincOS,IF(A5=Bajaj_TL_SNo,Bajaj_TL_PrincOS,0))),IF(L5<>"",L5,IF(UseFullUtil,K5,0))),0) -> 100 | N5: =IFERROR(M5/K5,0) -> 1 | O5: =IFERROR(K5-M5,0) -> 0 | P5: Fixed commission | Q5: 0 | R5: {=IFERROR(_xlfn.SWITCH(P5,"1Y MCLR (RBL Bank)",MCLR_RBL_1Y+Q5,"3M MCLR (YBL)",MCLR_YBL_3M+Q5,"6M I-MCLR (ICICI)",IMCLR_ICICI_6M+Q5,"12M MCLR (SIB)",MCLR_SIB_12M+Q5,"Bajaj Floating Reference Rate (BFRR)",BFRR_Bajaj+Q5,"Term SOFR (USD)",SOFR_3M+Q5,"3M T-Bill",TBill_3M+Q5,"Repo Rate",RepoRate+Q5,"FD rate",IFERROR(FD_Rate_RBL,0)+Q5,Q5),0)} -> 0 | S5: Fixed | T5: 0 | U5: On Maturity | V5: 6 | W5: 0 | X5: 46022 | Y5: =IFERROR(EDATE(X5,T5),"") -> 46022 | Z5: =IFERROR(EDATE(X5,V5),"") -> 46203 | AA5: 46022 | AB5: 46356 | AC5: Working capital incl. service LC issuance | AD5: 1st p-p on current assets; 2nd p-p on FA; Personal guarantee | AE5: RBL Renewal Letter dated 31-Dec-2025 | AF5: Pricing 0.45% effective 31-Dec-2025. | AG5: =TRUE() -> TRUE
A6: 2 | B6: RBL Bank | C6: Bank Guarantee | D6: NFB | E6: Revolving | F6: =TRUE() -> TRUE | G6: =FALSE() -> FALSE | H6: 0 | I6: INR | J6: 25 | K6: =IFERROR(J6,0) -> 25 | M6: =IFERROR(IF(D6="FB-Term",IF(A6=RBL_TL_SNo,RBL_TL_PrincOS,IF(A6=YBL_TL_SNo,YBL_TL_PrincOS,IF(A6=Bajaj_TL_SNo,Bajaj_TL_PrincOS,0))),IF(L6<>"",L6,IF(UseFullUtil,K6,0))),0) -> 25 | N6: =IFERROR(M6/K6,0) -> 1 | O6: =IFERROR(K6-M6,0) -> 0 | P6: Fixed commission | Q6: 0 | R6: {=IFERROR(_xlfn.SWITCH(P6,"1Y MCLR (RBL Bank)",MCLR_RBL_1Y+Q6,"3M MCLR (YBL)",MCLR_YBL_3M+Q6,"6M I-MCLR (ICICI)",IMCLR_ICICI_6M+Q6,"12M MCLR (SIB)",MCLR_SIB_12M+Q6,"Bajaj Floating Reference Rate (BFRR)",BFRR_Bajaj+Q6,"Term SOFR (USD)",SOFR_3M+Q6,"3M T-Bill",TBill_3M+Q6,"Repo Rate",RepoRate+Q6,"FD rate",IFERROR(FD_Rate_RBL,0)+Q6,Q6),0)} -> 0 | S6: Fixed | T6: 0 | U6: On Demand | V6: 12 | W6: 0 | X6: 46022 | Y6: =IFERROR(EDATE(X6,T6),"") -> 46022 | Z6: =IFERROR(EDATE(X6,V6),"") -> 46387 | AA6: 46022 | AB6: 46356 | AC6: PBG, Bid Bond, Govt/Semi-Govt guarantees | AD6: 1st p-p on current assets; 2nd p-p on FA; Personal guarantee | AE6: RBL Renewal Letter dated 31-Dec-2025 | AF6: BG commission 0.50% per 28-Feb-2025 pricing table. | AG6: =FALSE() -> FALSE
A7: 3 | B7: RBL Bank | C7: Invoice Discounting (PID) | D7: FB | E7: Revolving | F7: =TRUE() -> TRUE | G7: =FALSE() -> FALSE | H7: 0 | I7: INR | J7: 100 | K7: =IFERROR(J7,0) -> 100 | M7: =IFERROR(IF(D7="FB-Term",IF(A7=RBL_TL_SNo,RBL_TL_PrincOS,IF(A7=YBL_TL_SNo,YBL_TL_PrincOS,IF(A7=Bajaj_TL_SNo,Bajaj_TL_PrincOS,0))),IF(L7<>"",L7,IF(UseFullUtil,K7,0))),0) -> 100 | N7: =IFERROR(M7/K7,0) -> 1 | O7: =IFERROR(K7-M7,0) -> 0 | P7: 1Y MCLR (RBL Bank) | Q7: 0.005 | R7: {=IFERROR(_xlfn.SWITCH(P7,"1Y MCLR (RBL Bank)",MCLR_RBL_1Y+Q7,"3M MCLR (YBL)",MCLR_YBL_3M+Q7,"6M I-MCLR (ICICI)",IMCLR_ICICI_6M+Q7,"12M MCLR (SIB)",MCLR_SIB_12M+Q7,"Bajaj Floating Reference Rate (BFRR)",BFRR_Bajaj+Q7,"Term SOFR (USD)",SOFR_3M+Q7,"3M T-Bill",TBill_3M+Q7,"Repo Rate",RepoRate+Q7,"FD rate",IFERROR(FD_Rate_RBL,0)+Q7,Q7),0)} -> 0.095 | S7: Floating (Indicative) | T7: 0 | U7: On Maturity | V7: 1 | W7: 0 | X7: 46022 | Y7: =IFERROR(EDATE(X7,T7),"") -> 46022 | Z7: =IFERROR(EDATE(X7,V7),"") -> 46053 | AA7: 46022 | AB7: 46356 | AC7: Working capital | AD7: 1st p-p on current assets; 2nd p-p on FA; Personal guarantee | AE7: RBL Renewal Letter dated 31-Dec-2025 | AF7: Rate set at availment. Spread of 50 bps over 1Y MCLR is illustrative; rate confirmed at each availment per sanction letter. | AG7: =FALSE() -> FALSE
A8: 4 | B8: RBL Bank | C8: SBLC | D8: NFB | E8: Revolving | F8: =TRUE() -> TRUE | G8: =FALSE() -> FALSE | H8: 0 | I8: INR | J8: 100 | K8: =IFERROR(J8,0) -> 100 | M8: =IFERROR(IF(D8="FB-Term",IF(A8=RBL_TL_SNo,RBL_TL_PrincOS,IF(A8=YBL_TL_SNo,YBL_TL_PrincOS,IF(A8=Bajaj_TL_SNo,Bajaj_TL_PrincOS,0))),IF(L8<>"",L8,IF(UseFullUtil,K8,0))),0) -> 100 | N8: =IFERROR(M8/K8,0) -> 1 | O8: =IFERROR(K8-M8,0) -> 0 | P8: To be decided | Q8: 0.005 | R8: {=IFERROR(_xlfn.SWITCH(P8,"1Y MCLR (RBL Bank)",MCLR_RBL_1Y+Q8,"3M MCLR (YBL)",MCLR_YBL_3M+Q8,"6M I-MCLR (ICICI)",IMCLR_ICICI_6M+Q8,"12M MCLR (SIB)",MCLR_SIB_12M+Q8,"Bajaj Floating Reference Rate (BFRR)",BFRR_Bajaj+Q8,"Term SOFR (USD)",SOFR_3M+Q8,"3M T-Bill",TBill_3M+Q8,"Repo Rate",RepoRate+Q8,"FD rate",IFERROR(FD_Rate_RBL,0)+Q8,Q8),0)} -> 0.005 | S8: TBD | T8: 0 | U8: On Maturity | V8: 6 | W8: 0 | X8: 45729 | Y8: =IFERROR(EDATE(X8,T8),"") -> 45729 | Z8: =IFERROR(EDATE(X8,V8),"") -> 45913 | AA8: 45729 | AB8: 46356 | AC8: Buyer's Credit from RBL GIFT City / other banks | AD8: Same as LC | AE8: RBL Modification Letter dated 13-Mar-2025 | AF8: Sub-limit of LC (Main). | AG8: =FALSE() -> FALSE
A9: 5 | B9: RBL Bank | C9: Pre-Acceptance LCBD | D9: FB | E9: Revolving | F9: =TRUE() -> TRUE | G9: =FALSE() -> FALSE | H9: 0 | I9: INR | J9: 100 | K9: =IFERROR(J9,0) -> 100 | M9: =IFERROR(IF(D9="FB-Term",IF(A9=RBL_TL_SNo,RBL_TL_PrincOS,IF(A9=YBL_TL_SNo,YBL_TL_PrincOS,IF(A9=Bajaj_TL_SNo,Bajaj_TL_PrincOS,0))),IF(L9<>"",L9,IF(UseFullUtil,K9,0))),0) -> 100 | N9: =IFERROR(M9/K9,0) -> 1 | O9: =IFERROR(K9-M9,0) -> 0 | P9: 1Y MCLR (RBL Bank) | Q9: 0.0075 | R9: {=IFERROR(_xlfn.SWITCH(P9,"1Y MCLR (RBL Bank)",MCLR_RBL_1Y+Q9,"3M MCLR (YBL)",MCLR_YBL_3M+Q9,"6M I-MCLR (ICICI)",IMCLR_ICICI_6M+Q9,"12M MCLR (SIB)",MCLR_SIB_12M+Q9,"Bajaj Floating Reference Rate (BFRR)",BFRR_Bajaj+Q9,"Term SOFR (USD)",SOFR_3M+Q9,"3M T-Bill",TBill_3M+Q9,"Repo Rate",RepoRate+Q9,"FD rate",IFERROR(FD_Rate_RBL,0)+Q9,Q9),0)} -> 0.0975 | S9: Floating (Indicative) | T9: 0 | U9: On Maturity | V9: 0 | W9: 0 | X9: 46022 | Y9: =IFERROR(EDATE(X9,T9),"") -> 46022 | Z9: =IFERROR(EDATE(X9,V9),"") -> 46022 | AA9: 46022 | AB9: 46356 | AC9: Working capital | AD9: 1st p-p on current assets; 2nd p-p on FA; Personal guarantee | AE9: RBL Renewal Letter dated 31-Dec-2025 | AF9: Rate set at availment. Spread of 75 bps over 1Y MCLR is illustrative; rate confirmed at each availment per sanction letter. | AG9: =FALSE() -> FALSE
A10: 6 | B10: RBL Bank | C10: Cash Credit | D10: FB | E10: Revolving | F10: =TRUE() -> TRUE | G10: =FALSE() -> FALSE | H10: 0 | I10: INR | J10: 100 | K10: =IFERROR(J10,0) -> 100 | M10: =IFERROR(IF(D10="FB-Term",IF(A10=RBL_TL_SNo,RBL_TL_PrincOS,IF(A10=YBL_TL_SNo,YBL_TL_PrincOS,IF(A10=Bajaj_TL_SNo,Bajaj_TL_PrincOS,0))),IF(L10<>"",L10,IF(UseFullUtil,K10,0))),0) -> 100 | N10: =IFERROR(M10/K10,0) -> 1 | O10: =IFERROR(K10-M10,0) -> 0 | P10: 1Y MCLR (RBL Bank) | Q10: 0.0005 | R10: {=IFERROR(_xlfn.SWITCH(P10,"1Y MCLR (RBL Bank)",MCLR_RBL_1Y+Q10,"3M MCLR (YBL)",MCLR_YBL_3M+Q10,"6M I-MCLR (ICICI)",IMCLR_ICICI_6M+Q10,"12M MCLR (SIB)",MCLR_SIB_12M+Q10,"Bajaj Floating Reference Rate (BFRR)",BFRR_Bajaj+Q10,"Term SOFR (USD)",SOFR_3M+Q10,"3M T-Bill",TBill_3M+Q10,"Repo Rate",RepoRate+Q10,"FD rate",IFERROR(FD_Rate_RBL,0)+Q10,Q10),0)} -> 0.0905 | S10: Floating | T10: 0 | U10: On Demand | V10: 0 | W10: 0 | X10: 45716 | Y10: =IFERROR(EDATE(X10,T10),"") -> 45716 | Z10: =IFERROR(EDATE(X10,V10),"") -> 45716 | AA10: 45716 | AB10: 46356 | AC10: Working capital | AD10: 1st p-p on current assets; 2nd p-p on FA; Personal guarantee | AE10: RBL Renewal cum Modification dated 28-Feb-2025 | AF10: 1Y MCLR + 5 bps. | AG10: =FALSE() -> FALSE
A11: 7 | B11: RBL Bank | C11: Working Capital Demand Loan (WCDL) | D11: FB | E11: Revolving | F11: =TRUE() -> TRUE | G11: =FALSE() -> FALSE | H11: 0 | I11: INR | J11: 100 | K11: =IFERROR(J11,0) -> 100 | M11: =IFERROR(IF(D11="FB-Term",IF(A11=RBL_TL_SNo,RBL_TL_PrincOS,IF(A11=YBL_TL_SNo,YBL_TL_PrincOS,IF(A11=Bajaj_TL_SNo,Bajaj_TL_PrincOS,0))),IF(L11<>"",L11,IF(UseFullUtil,K11,0))),0) -> 100 | N11: =IFERROR(M11/K11,0) -> 1 | O11: =IFERROR(K11-M11,0) -> 0 | P11: To be decided | Q11: 0 | R11: {=IFERROR(_xlfn.SWITCH(P11,"1Y MCLR (RBL Bank)",MCLR_RBL_1Y+Q11,"3M MCLR (YBL)",MCLR_YBL_3M+Q11,"6M I-MCLR (ICICI)",IMCLR_ICICI_6M+Q11,"12M MCLR (SIB)",MCLR_SIB_12M+Q11,"Bajaj Floating Reference Rate (BFRR)",BFRR_Bajaj+Q11,"Term SOFR (USD)",SOFR_3M+Q11,"3M T-Bill",TBill_3M+Q11,"Repo Rate",RepoRate+Q11,"FD rate",IFERROR(FD_Rate_RBL,0)+Q11,Q11),0)} -> 0 | S11: TBD | T11: 0 | U11: On Demand | V11: 4 | W11: 0 | X11: 46022 | Y11: =IFERROR(EDATE(X11,T11),"") -> 46022 | Z11: =IFERROR(EDATE(X11,V11),"") -> 46142 | AA11: 46022 | AB11: 46356 | AC11: Working capital | AD11: 1st p-p on current assets; 2nd p-p on FA; Personal guarantee | AE11: RBL Renewal Letter dated 31-Dec-2025 | AF11: Rate set at drawdown. | AG11: =FALSE() -> FALSE
A12: 8 | B12: RBL Bank | C12: Loan Equivalent Risk (LER) | D12: Hedge | E12: Revolving | F12: =TRUE() -> TRUE | G12: =FALSE() -> FALSE | H12: 0 | I12: INR | J12: 20 | K12: =IFERROR(J12,0) -> 20 | M12: =IFERROR(IF(D12="FB-Term",IF(A12=RBL_TL_SNo,RBL_TL_PrincOS,IF(A12=YBL_TL_SNo,YBL_TL_PrincOS,IF(A12=Bajaj_TL_SNo,Bajaj_TL_PrincOS,0))),IF(L12<>"",L12,IF(UseFullUtil,K12,0))),0) -> 20 | N12: =IFERROR(M12/K12,0) -> 1 | O12: =IFERROR(K12-M12,0) -> 0 | P12: Bank treasury | Q12: 0 | R12: {=IFERROR(_xlfn.SWITCH(P12,"1Y MCLR (RBL Bank)",MCLR_RBL_1Y+Q12,"3M MCLR (YBL)",MCLR_YBL_3M+Q12,"6M I-MCLR (ICICI)",IMCLR_ICICI_6M+Q12,"12M MCLR (SIB)",MCLR_SIB_12M+Q12,"Bajaj Floating Reference Rate (BFRR)",BFRR_Bajaj+Q12,"Term SOFR (USD)",SOFR_3M+Q12,"3M T-Bill",TBill_3M+Q12,"Repo Rate",RepoRate+Q12,"FD rate",IFERROR(FD_Rate_RBL,0)+Q12,Q12),0)} -> 0 | S12: Fixed | T12: 0 | U12: On Settlement | V12: 12 | W12: 0 | X12: 46022 | Y12: =IFERROR(EDATE(X12,T12),"") -> 46022 | Z12: =IFERROR(EDATE(X12,V12),"") -> 46387 | AA12: 46022 | AB12: 46356 | AC12: Forex hedging (MTM cap 75%) | AD12: Unsecured | AE12: RBL Renewal Letter dated 31-Dec-2025 | AF12: Notional limit; 75% MTM trigger. | AG12: =FALSE() -> FALSE
A13: 9 | B13: RBL Bank | C13: Term Loan | D13: FB-Term | E13: Non-Revolving | F13: =FALSE() -> FALSE | G13: =FALSE() -> FALSE | H13: 1 | I13: INR | J13: 200 | K13: =IFERROR(J13,0) -> 200 | M13: =IFERROR(IF(D13="FB-Term",IF(A13=RBL_TL_SNo,RBL_TL_PrincOS,IF(A13=YBL_TL_SNo,YBL_TL_PrincOS,IF(A13=Bajaj_TL_SNo,Bajaj_TL_PrincOS,0))),IF(L13<>"",L13,IF(UseFullUtil,K13,0))),0) -> 0 | N13: =IFERROR(M13/K13,0) -> 0 | O13: =IFERROR(K13-M13,0) -> 200 | P13: 1Y MCLR (RBL Bank) | Q13: 0.0075 | R13: {=IFERROR(_xlfn.SWITCH(P13,"1Y MCLR (RBL Bank)",MCLR_RBL_1Y+Q13,"3M MCLR (YBL)",MCLR_YBL_3M+Q13,"6M I-MCLR (ICICI)",IMCLR_ICICI_6M+Q13,"12M MCLR (SIB)",MCLR_SIB_12M+Q13,"Bajaj Floating Reference Rate (BFRR)",BFRR_Bajaj+Q13,"Term SOFR (USD)",SOFR_3M+Q13,"3M T-Bill",TBill_3M+Q13,"Repo Rate",RepoRate+Q13,"FD rate",IFERROR(FD_Rate_RBL,0)+Q13,Q13),0)} -> 0.0975 | S13: Floating (Indicative) | T13: 24 | U13: Quarterly | V13: 60 | W13: 12 | X13: 45315 | Y13: =IFERROR(EDATE(X13,T13),"") -> 46046 | Z13: =RBL_TL_Maturity -> 47208 | AA13: 45315 | AB13: 46387 | AC13: Repayment of existing SBLC/BC + fresh capex | AD13: 1st p-p on FA; 1st p-p mortgage on immovable; 2nd p-p on CA | AE13: RBL TL Sanction | AF13: Indicative 9.75% (1Y MCLR + 75 bps); confirm with RBL at drawdown. | AG13: =FALSE() -> FALSE
A14: 10 | B14: RBL Bank | C14: SBLC for Buyer's Credit (GIFT City) | D14: NFB | E14: Revolving | F14: =TRUE() -> TRUE | G14: =FALSE() -> FALSE | H14: 0 | I14: INR | J14: 190 | K14: =IFERROR(J14,0) -> 190 | M14: =IFERROR(IF(D14="FB-Term",IF(A14=RBL_TL_SNo,RBL_TL_PrincOS,IF(A14=YBL_TL_SNo,YBL_TL_PrincOS,IF(A14=Bajaj_TL_SNo,Bajaj_TL_PrincOS,0))),IF(L14<>"",L14,IF(UseFullUtil,K14,0))),0) -> 190 | N14: =IFERROR(M14/K14,0) -> 1 | O14: =IFERROR(K14-M14,0) -> 0 | P14: Fixed commission | Q14: 0.005 | R14: {=IFERROR(_xlfn.SWITCH(P14,"1Y MCLR (RBL Bank)",MCLR_RBL_1Y+Q14,"3M MCLR (YBL)",MCLR_YBL_3M+Q14,"6M I-MCLR (ICICI)",IMCLR_ICICI_6M+Q14,"12M MCLR (SIB)",MCLR_SIB_12M+Q14,"Bajaj Floating Reference Rate (BFRR)",BFRR_Bajaj+Q14,"Term SOFR (USD)",SOFR_3M+Q14,"3M T-Bill",TBill_3M+Q14,"Repo Rate",RepoRate+Q14,"FD rate",IFERROR(FD_Rate_RBL,0)+Q14,Q14),0)} -> 0.005 | S14: Fixed | T14: 0 | U14: On Maturity | V14: 36 | W14: 0 | X14: 46022 | Y14: =IFERROR(EDATE(X14,T14),"") -> 46022 | Z14: =IFERROR(EDATE(X14,V14),"") -> 47118 | AA14: 46022 | AB14: 46356 | AC14: Buyer's credit through RBL GIFT City or other banks | AD14: 1st p-p on FA; 1st p-p mortgage on immovable; 2nd p-p on CA | AE14: RBL Renewal Letter dated 31-Dec-2025 | AF14: Limit increased 172 → 190 Cr on 31-Dec-2025. | AG14: =TRUE() -> TRUE
A15: 11 | B15: RBL Bank | C15: Capex LC | D15: NFB | E15: Revolving | F15: =TRUE() -> TRUE | G15: =FALSE() -> FALSE | H15: 0 | I15: INR | J15: 25 | K15: =IFERROR(J15,0) -> 25 | M15: =IFERROR(IF(D15="FB-Term",IF(A15=RBL_TL_SNo,RBL_TL_PrincOS,IF(A15=YBL_TL_SNo,YBL_TL_PrincOS,IF(A15=Bajaj_TL_SNo,Bajaj_TL_PrincOS,0))),IF(L15<>"",L15,IF(UseFullUtil,K15,0))),0) -> 25 | N15: =IFERROR(M15/K15,0) -> 1 | O15: =IFERROR(K15-M15,0) -> 0 | P15: Fixed commission | Q15: 0.005 | R15: {=IFERROR(_xlfn.SWITCH(P15,"1Y MCLR (RBL Bank)",MCLR_RBL_1Y+Q15,"3M MCLR (YBL)",MCLR_YBL_3M+Q15,"6M I-MCLR (ICICI)",IMCLR_ICICI_6M+Q15,"12M MCLR (SIB)",MCLR_SIB_12M+Q15,"Bajaj Floating Reference Rate (BFRR)",BFRR_Bajaj+Q15,"Term SOFR (USD)",SOFR_3M+Q15,"3M T-Bill",TBill_3M+Q15,"Repo Rate",RepoRate+Q15,"FD rate",IFERROR(FD_Rate_RBL,0)+Q15,Q15),0)} -> 0.005 | S15: Fixed | T15: 0 | U15: On Maturity | V15: 36 | W15: 0 | X15: 46022 | Y15: =IFERROR(EDATE(X15,T15),"") -> 46022 | Z15: =IFERROR(EDATE(X15,V15),"") -> 47118 | AA15: 46022 | AB15: 46356 | AC15: Purchase of capital goods | AD15: 1st p-p on FA; 1st p-p mortgage on immovable; 2nd p-p on CA | AE15: RBL Renewal Letter dated 31-Dec-2025 | AF15: Originally 24-Jan-2024; converted revolving 28-Feb-2025. | AG15: =TRUE() -> TRUE
A16: 12 | B16: RBL Bank | C16: Overdraft backed by 100% FD (FDOD) | D16: FB-FDbacked | E16: Revolving | F16: =FALSE() -> FALSE | G16: =TRUE() -> TRUE | H16: 3 | I16: INR | J16: 100 | K16: =IFERROR(J16,0) -> 100 | M16: =IFERROR(IF(D16="FB-Term",IF(A16=RBL_TL_SNo,RBL_TL_PrincOS,IF(A16=YBL_TL_SNo,YBL_TL_PrincOS,IF(A16=Bajaj_TL_SNo,Bajaj_TL_PrincOS,0))),IF(L16<>"",L16,IF(UseFullUtil,K16,0))),0) -> 100 | N16: =IFERROR(M16/K16,0) -> 1 | O16: =IFERROR(K16-M16,0) -> 0 | P16: FD rate | Q16: 0.0025 | R16: {=IFERROR(_xlfn.SWITCH(P16,"1Y MCLR (RBL Bank)",MCLR_RBL_1Y+Q16,"3M MCLR (YBL)",MCLR_YBL_3M+Q16,"6M I-MCLR (ICICI)",IMCLR_ICICI_6M+Q16,"12M MCLR (SIB)",MCLR_SIB_12M+Q16,"Bajaj Floating Reference Rate (BFRR)",BFRR_Bajaj+Q16,"Term SOFR (USD)",SOFR_3M+Q16,"3M T-Bill",TBill_3M+Q16,"Repo Rate",RepoRate+Q16,"FD rate",IFERROR(FD_Rate_RBL,0)+Q16,Q16),0)} -> 0.0725 | S16: Floating | T16: 0 | U16: On Demand | V16: 12 | W16: 0 | X16: 45315 | Y16: =IFERROR(EDATE(X16,T16),"") -> 45315 | Z16: =IFERROR(EDATE(X16,V16),"") -> 45681 | AA16: 45315 | AB16: 46356 | AC16: Cash flow mismatches | AD16: Exclusive charge on FD = 100% of facility | AE16: RBL Renewal cum Enhancement dated 24-Jan-2024 | AF16: Excluded from INR 300 Cr overall cap. | AG16: =FALSE() -> FALSE
A17: 13 | B17: RBL Bank | C17: LC backed by 100% FD | D17: NFB-FDbacked | E17: Revolving | F17: =TRUE() -> TRUE | G17: =TRUE() -> TRUE | H17: 0 | I17: INR | J17: 50 | K17: =IFERROR(J17,0) -> 50 | M17: =IFERROR(IF(D17="FB-Term",IF(A17=RBL_TL_SNo,RBL_TL_PrincOS,IF(A17=YBL_TL_SNo,YBL_TL_PrincOS,IF(A17=Bajaj_TL_SNo,Bajaj_TL_PrincOS,0))),IF(L17<>"",L17,IF(UseFullUtil,K17,0))),0) -> 50 | N17: =IFERROR(M17/K17,0) -> 1 | O17: =IFERROR(K17-M17,0) -> 0 | P17: To be decided | Q17: 0 | R17: {=IFERROR(_xlfn.SWITCH(P17,"1Y MCLR (RBL Bank)",MCLR_RBL_1Y+Q17,"3M MCLR (YBL)",MCLR_YBL_3M+Q17,"6M I-MCLR (ICICI)",IMCLR_ICICI_6M+Q17,"12M MCLR (SIB)",MCLR_SIB_12M+Q17,"Bajaj Floating Reference Rate (BFRR)",BFRR_Bajaj+Q17,"Term SOFR (USD)",SOFR_3M+Q17,"3M T-Bill",TBill_3M+Q17,"Repo Rate",RepoRate+Q17,"FD rate",IFERROR(FD_Rate_RBL,0)+Q17,Q17),0)} -> 0 | S17: TBD | T17: 0 | U17: On Maturity | V17: 12 | W17: 0 | X17: 45315 | Y17: =IFERROR(EDATE(X17,T17),"") -> 45315 | Z17: =IFERROR(EDATE(X17,V17),"") -> 45681 | AA17: 45315 | AB17: 46356 | AC17: WC - import/purchase of raw materials | AD17: Exclusive charge on FD = 100% of facility | AE17: RBL Renewal cum Enhancement dated 24-Jan-2024 | AF17: Sub-limit of FDOD. | AG17: =FALSE() -> FALSE
A18: 14 | B18: RBL Bank | C18: Buyer's Credit from GIFT City - WC | D18: FB-FCY | E18: Revolving | F18: =TRUE() -> TRUE | G18: =FALSE() -> FALSE | H18: 0 | I18: USD | J18: 11 | K18: 100 | M18: =IFERROR(IF(D18="FB-Term",IF(A18=RBL_TL_SNo,RBL_TL_PrincOS,IF(A18=YBL_TL_SNo,YBL_TL_PrincOS,IF(A18=Bajaj_TL_SNo,Bajaj_TL_PrincOS,0))),IF(L18<>"",L18,IF(UseFullUtil,K18,0))),0) -> 100 | N18: =IFERROR(M18/K18,0) -> 1 | O18: =IFERROR(K18-M18,0) -> 0 | P18: Term SOFR (USD) | Q18: 0 | R18: {=IFERROR(_xlfn.SWITCH(P18,"1Y MCLR (RBL Bank)",MCLR_RBL_1Y+Q18,"3M MCLR (YBL)",MCLR_YBL_3M+Q18,"6M I-MCLR (ICICI)",IMCLR_ICICI_6M+Q18,"12M MCLR (SIB)",MCLR_SIB_12M+Q18,"Bajaj Floating Reference Rate (BFRR)",BFRR_Bajaj+Q18,"Term SOFR (USD)",SOFR_3M+Q18,"3M T-Bill",TBill_3M+Q18,"Repo Rate",RepoRate+Q18,"FD rate",IFERROR(FD_Rate_RBL,0)+Q18,Q18),0)} -> 0.043 | S18: Floating | T18: 0 | U18: Bullet | V18: 6 | W18: 1 | X18: 45729 | Y18: =IFERROR(EDATE(X18,T18),"") -> 45729 | Z18: =IFERROR(EDATE(X18,V18),"") -> 45913 | AA18: 45729 | AB18: 46356 | AC18: Working capital | AD18: RBL-issued BG/SBLC | AE18: RBL Buyer's Credit WC Sanction dated 13-Mar-2025 | AF18: INR-capped at ₹100 Cr. | AG18: =FALSE() -> FALSE
A19: 15 | B19: RBL Bank | C19: Buyer's Credit from GIFT City - CAPEX | D19: FB-FCY | E19: Revolving | F19: =TRUE() -> TRUE | G19: =FALSE() -> FALSE | H19: 0 | I19: USD | J19: 20 | K19: 172 | M19: =IFERROR(IF(D19="FB-Term",IF(A19=RBL_TL_SNo,RBL_TL_PrincOS,IF(A19=YBL_TL_SNo,YBL_TL_PrincOS,IF(A19=Bajaj_TL_SNo,Bajaj_TL_PrincOS,0))),IF(L19<>"",L19,IF(UseFullUtil,K19,0))),0) -> 172 | N19: =IFERROR(M19/K19,0) -> 1 | O19: =IFERROR(K19-M19,0) -> 0 | P19: Term SOFR (USD) | Q19: 0 | R19: {=IFERROR(_xlfn.SWITCH(P19,"1Y MCLR (RBL Bank)",MCLR_RBL_1Y+Q19,"3M MCLR (YBL)",MCLR_YBL_3M+Q19,"6M I-MCLR (ICICI)",IMCLR_ICICI_6M+Q19,"12M MCLR (SIB)",MCLR_SIB_12M+Q19,"Bajaj Floating Reference Rate (BFRR)",BFRR_Bajaj+Q19,"Term SOFR (USD)",SOFR_3M+Q19,"3M T-Bill",TBill_3M+Q19,"Repo Rate",RepoRate+Q19,"FD rate",IFERROR(FD_Rate_RBL,0)+Q19,Q19),0)} -> 0.043 | S19: Floating | T19: 0 | U19: Bullet | V19: 36 | W19: 1 | X19: 45743 | Y19: =IFERROR(EDATE(X19,T19),"") -> 45743 | Z19: =IFERROR(EDATE(X19,V19),"") -> 46839 | AA19: 45743 | AB19: 46356 | AC19: CAPEX funding | AD19: RBL-issued BG/SBLC | AE19: RBL Buyer's Credit CAPEX Sanction dated 27-Mar-2025 | AF19: INR-capped at ₹172 Cr. | AG19: =FALSE() -> FALSE
A20: 16 | B20: YES Bank | C20: Purchase Invoice Financing | D20: FB | E20: Revolving | F20: =TRUE() -> TRUE | G20: =FALSE() -> FALSE | H20: 0 | I20: INR | J20: 100 | K20: =IFERROR(J20,0) -> 100 | M20: =IFERROR(IF(D20="FB-Term",IF(A20=RBL_TL_SNo,RBL_TL_PrincOS,IF(A20=YBL_TL_SNo,YBL_TL_PrincOS,IF(A20=Bajaj_TL_SNo,Bajaj_TL_PrincOS,0))),IF(L20<>"",L20,IF(UseFullUtil,K20,0))),0) -> 100 | N20: =IFERROR(M20/K20,0) -> 1 | O20: =IFERROR(K20-M20,0) -> 0 | P20: 3M MCLR (YBL) | Q20: 0.005 | R20: {=IFERROR(_xlfn.SWITCH(P20,"1Y MCLR (RBL Bank)",MCLR_RBL_1Y+Q20,"3M MCLR (YBL)",MCLR_YBL_3M+Q20,"6M I-MCLR (ICICI)",IMCLR_ICICI_6M+Q20,"12M MCLR (SIB)",MCLR_SIB_12M+Q20,"Bajaj Floating Reference Rate (BFRR)",BFRR_Bajaj+Q20,"Term SOFR (USD)",SOFR_3M+Q20,"3M T-Bill",TBill_3M+Q20,"Repo Rate",RepoRate+Q20,"FD rate",IFERROR(FD_Rate_RBL,0)+Q20,Q20),0)} -> 0.095 | S20: TBD | T20: 0 | U20: On Maturity | V20: 3 | W20: 0 | X20: 46100 | Y20: =IFERROR(EDATE(X20,T20),"") -> 46100 | Z20: =IFERROR(EDATE(X20,V20),"") -> 46192 | AA20: 46100 | AB20: 46142 | AC20: Working capital | AD20: 1st p-p hypothecation over current assets | AE20: YBL Renewal cum Addendum dated 19-Mar-2026 | AF20: New facility; interest payable upfront. | AG20: =FALSE() -> FALSE
A21: 17 | B21: YES Bank | C21: Cash Credit | D21: FB | E21: Revolving | F21: =TRUE() -> TRUE | G21: =FALSE() -> FALSE | H21: 0 | I21: INR | J21: 25 | K21: =IFERROR(J21,0) -> 25 | M21: =IFERROR(IF(D21="FB-Term",IF(A21=RBL_TL_SNo,RBL_TL_PrincOS,IF(A21=YBL_TL_SNo,YBL_TL_PrincOS,IF(A21=Bajaj_TL_SNo,Bajaj_TL_PrincOS,0))),IF(L21<>"",L21,IF(UseFullUtil,K21,0))),0) -> 25 | N21: =IFERROR(M21/K21,0) -> 1 | O21: =IFERROR(K21-M21,0) -> 0 | P21: 3M MCLR (YBL) | Q21: 0.0007 | R21: {=IFERROR(_xlfn.SWITCH(P21,"1Y MCLR (RBL Bank)",MCLR_RBL_1Y+Q21,"3M MCLR (YBL)",MCLR_YBL_3M+Q21,"6M I-MCLR (ICICI)",IMCLR_ICICI_6M+Q21,"12M MCLR (SIB)",MCLR_SIB_12M+Q21,"Bajaj Floating Reference Rate (BFRR)",BFRR_Bajaj+Q21,"Term SOFR (USD)",SOFR_3M+Q21,"3M T-Bill",TBill_3M+Q21,"Repo Rate",RepoRate+Q21,"FD rate",IFERROR(FD_Rate_RBL,0)+Q21,Q21),0)} -> 0.0907 | S21: Floating | T21: 0 | U21: On Demand | V21: 12 | W21: 0 | X21: 46100 | Y21: =IFERROR(EDATE(X21,T21),"") -> 46100 | Z21: =IFERROR(EDATE(X21,V21),"") -> 46465 | AA21: 46100 | AB21: 46490 | AC21: Working capital | AD21: 1st p-p on CA; mortgage on Faridabad property; 2nd p-p on FA; Personal Guarantee | AE21: YBL Renewal cum Addendum dated 19-Mar-2026 | AF21: Pricing moved to 3M MCLR + 7 bps on 19-Mar-2026. | AG21: =FALSE() -> FALSE
A22: 18 | B22: YES Bank | C22: Letter of Credit | D22: NFB | E22: Revolving | F22: =FALSE() -> FALSE | G22: =FALSE() -> FALSE | H22: 2 | I22: INR | J22: 200 | K22: =IFERROR(J22,0) -> 200 | M22: =IFERROR(IF(D22="FB-Term",IF(A22=RBL_TL_SNo,RBL_TL_PrincOS,IF(A22=YBL_TL_SNo,YBL_TL_PrincOS,IF(A22=Bajaj_TL_SNo,Bajaj_TL_PrincOS,0))),IF(L22<>"",L22,IF(UseFullUtil,K22,0))),0) -> 200 | N22: =IFERROR(M22/K22,0) -> 1 | O22: =IFERROR(K22-M22,0) -> 0 | P22: Fixed commission | Q22: 0 | R22: {=IFERROR(_xlfn.SWITCH(P22,"1Y MCLR (RBL Bank)",MCLR_RBL_1Y+Q22,"3M MCLR (YBL)",MCLR_YBL_3M+Q22,"6M I-MCLR (ICICI)",IMCLR_ICICI_6M+Q22,"12M MCLR (SIB)",MCLR_SIB_12M+Q22,"Bajaj Floating Reference Rate (BFRR)",BFRR_Bajaj+Q22,"Term SOFR (USD)",SOFR_3M+Q22,"3M T-Bill",TBill_3M+Q22,"Repo Rate",RepoRate+Q22,"FD rate",IFERROR(FD_Rate_RBL,0)+Q22,Q22),0)} -> 0 | S22: Fixed | T22: 0 | U22: On Maturity | V22: 7 | W22: 0 | X22: 46100 | Y22: =IFERROR(EDATE(X22,T22),"") -> 46100 | Z22: =IFERROR(EDATE(X22,V22),"") -> 46314 | AA22: 46100 | AB22: 46472 | AC22: Procurement of raw materials | AD22: 1st p-p on CA; mortgage on Faridabad property; 2nd p-p on FA; Personal Guarantee | AE22: YBL Renewal cum Addendum dated 19-Mar-2026 | AF22: Overall WC cap INR 200 Cr net of receivable finance. | AG22: =TRUE() -> TRUE
A23: 19 | B23: YES Bank | C23: Financial BG / SBLC | D23: NFB | E23: Revolving | F23: =TRUE() -> TRUE | G23: =FALSE() -> FALSE | H23: 0 | I23: INR | J23: 200 | K23: =IFERROR(J23,0) -> 200 | M23: =IFERROR(IF(D23="FB-Term",IF(A23=RBL_TL_SNo,RBL_TL_PrincOS,IF(A23=YBL_TL_SNo,YBL_TL_PrincOS,IF(A23=Bajaj_TL_SNo,Bajaj_TL_PrincOS,0))),IF(L23<>"",L23,IF(UseFullUtil,K23,0))),0) -> 200 | N23: =IFERROR(M23/K23,0) -> 1 | O23: =IFERROR(K23-M23,0) -> 0 | P23: Fixed commission | Q23: 0.005 | R23: {=IFERROR(_xlfn.SWITCH(P23,"1Y MCLR (RBL Bank)",MCLR_RBL_1Y+Q23,"3M MCLR (YBL)",MCLR_YBL_3M+Q23,"6M I-MCLR (ICICI)",IMCLR_ICICI_6M+Q23,"12M MCLR (SIB)",MCLR_SIB_12M+Q23,"Bajaj Floating Reference Rate (BFRR)",BFRR_Bajaj+Q23,"Term SOFR (USD)",SOFR_3M+Q23,"3M T-Bill",TBill_3M+Q23,"Repo Rate",RepoRate+Q23,"FD rate",IFERROR(FD_Rate_RBL,0)+Q23,Q23),0)} -> 0.005 | S23: Fixed | T23: 0 | U23: On Maturity | V23: 6 | W23: 0 | X23: 46100 | Y23: =IFERROR(EDATE(X23,T23),"") -> 46100 | Z23: =IFERROR(EDATE(X23,V23),"") -> 46284 | AA23: 46100 | AB23: 46490 | AC23: Securing payment for raw materials / paper | AD23: 1st p-p on CA; mortgage on Faridabad property; 2nd p-p on FA; Personal Guarantee | AE23: YBL Renewal cum Addendum dated 19-Mar-2026 | AF23: Sub-limit of LC (Main). | AG23: =FALSE() -> FALSE
A24: 20 | B24: YES Bank | C24: Working Capital Demand Loan (WCDL) | D24: FB | E24: Revolving | F24: =TRUE() -> TRUE | G24: =FALSE() -> FALSE | H24: 0 | I24: INR | J24: 50 | K24: =IFERROR(J24,0) -> 50 | M24: =IFERROR(IF(D24="FB-Term",IF(A24=RBL_TL_SNo,RBL_TL_PrincOS,IF(A24=YBL_TL_SNo,YBL_TL_PrincOS,IF(A24=Bajaj_TL_SNo,Bajaj_TL_PrincOS,0))),IF(L24<>"",L24,IF(UseFullUtil,K24,0))),0) -> 50 | N24: =IFERROR(M24/K24,0) -> 1 | O24: =IFERROR(K24-M24,0) -> 0 | P24: To be decided | Q24: 0 | R24: {=IFERROR(_xlfn.SWITCH(P24,"1Y MCLR (RBL Bank)",MCLR_RBL_1Y+Q24,"3M MCLR (YBL)",MCLR_YBL_3M+Q24,"6M I-MCLR (ICICI)",IMCLR_ICICI_6M+Q24,"12M MCLR (SIB)",MCLR_SIB_12M+Q24,"Bajaj Floating Reference Rate (BFRR)",BFRR_Bajaj+Q24,"Term SOFR (USD)",SOFR_3M+Q24,"3M T-Bill",TBill_3M+Q24,"Repo Rate",RepoRate+Q24,"FD rate",IFERROR(FD_Rate_RBL,0)+Q24,Q24),0)} -> 0 | S24: TBD | T24: 0 | U24: On Demand | V24: 6 | W24: 0 | X24: 46100 | Y24: =IFERROR(EDATE(X24,T24),"") -> 46100 | Z24: =IFERROR(EDATE(X24,V24),"") -> 46284 | AA24: 46100 | AB24: 46490 | AC24: Working capital | AD24: 1st p-p on CA; mortgage on Faridabad property; 2nd p-p on FA; Personal Guarantee | AE24: YBL Renewal cum Addendum dated 19-Mar-2026 | AF24: Min utilisation covenant: 40% of YBL limits. | AG24: =FALSE() -> FALSE
A25: 21 | B25: YES Bank | C25: Term Loan (Refinance Canara) | D25: FB-Term | E25: Non-Revolving | F25: =FALSE() -> FALSE | G25: =FALSE() -> FALSE | H25: 1 | I25: INR | J25: 320.7 | K25: =IFERROR(J25,0) -> 320.7 | M25: =IFERROR(IF(D25="FB-Term",IF(A25=RBL_TL_SNo,RBL_TL_PrincOS,IF(A25=YBL_TL_SNo,YBL_TL_PrincOS,IF(A25=Bajaj_TL_SNo,Bajaj_TL_PrincOS,0))),IF(L25<>"",L25,IF(UseFullUtil,K25,0))),0) -> 295.9612 | N25: =IFERROR(M25/K25,0) -> 0.92285999 | O25: =IFERROR(K25-M25,0) -> 24.7388 | P25: 3M T-Bill | Q25: 0.0252 | R25: {=IFERROR(_xlfn.SWITCH(P25,"1Y MCLR (RBL Bank)",MCLR_RBL_1Y+Q25,"3M MCLR (YBL)",MCLR_YBL_3M+Q25,"6M I-MCLR (ICICI)",IMCLR_ICICI_6M+Q25,"12M MCLR (SIB)",MCLR_SIB_12M+Q25,"Bajaj Floating Reference Rate (BFRR)",BFRR_Bajaj+Q25,"Term SOFR (USD)",SOFR_3M+Q25,"3M T-Bill",TBill_3M+Q25,"Repo Rate",RepoRate+Q25,"FD rate",IFERROR(FD_Rate_RBL,0)+Q25,Q25),0)} -> 0.077 | S25: Floating | T25: 0 | U25: Quarterly | V25: 146 | W25: 46 | X25: 45642 | Y25: 45838 | Z25: =YBL_TL_Maturity -> 49948 | AA25: 45744 | AB25: 46253 | AC25: Refinance Canara TL + reimburse promoter loan + IA | AD25: 2nd p-p on CA; 1st p-p on FA; 1st p-p EM Kalinga Nagar | AE25: YBL TL Addendum dated 28-Mar-2025 | AF25: 47 EQI of ₹6.82 Cr per sanction letter 16-Dec-2024. | AG25: =FALSE() -> FALSE
A26: 22 | B26: Bajaj Finance | C26: Term Loan | D26: FB-Term | E26: Non-Revolving | F26: =FALSE() -> FALSE | G26: =FALSE() -> FALSE | H26: 1 | I26: INR | J26: 150 | K26: =IFERROR(J26,0) -> 150 | M26: =IFERROR(IF(D26="FB-Term",IF(A26=RBL_TL_SNo,RBL_TL_PrincOS,IF(A26=YBL_TL_SNo,YBL_TL_PrincOS,IF(A26=Bajaj_TL_SNo,Bajaj_TL_PrincOS,0))),IF(L26<>"",L26,IF(UseFullUtil,K26,0))),0) -> 150 | N26: =IFERROR(M26/K26,0) -> 1 | O26: =IFERROR(K26-M26,0) -> 0 | P26: Bajaj Floating Reference Rate (BFRR) | Q26: 0.001 | R26: {=IFERROR(_xlfn.SWITCH(P26,"1Y MCLR (RBL Bank)",MCLR_RBL_1Y+Q26,"3M MCLR (YBL)",MCLR_YBL_3M+Q26,"6M I-MCLR (ICICI)",IMCLR_ICICI_6M+Q26,"12M MCLR (SIB)",MCLR_SIB_12M+Q26,"Bajaj Floating Reference Rate (BFRR)",BFRR_Bajaj+Q26,"Term SOFR (USD)",SOFR_3M+Q26,"3M T-Bill",TBill_3M+Q26,"Repo Rate",RepoRate+Q26,"FD rate",IFERROR(FD_Rate_RBL,0)+Q26,Q26),0)} -> 0.086 | S26: Floating | T26: 12 | U26: Quarterly | V26: 96 | W26: 28 | X26: 45894 | Y26: 46361 | Z26: =Bajaj_TL_Maturity -> 48816 | AA26: 45887 | AB26: 45894 | AC26: CAPEX reimbursement + CAPEX + GCP | AD26: 1st p-p on FA at Coke Plant Khurunti; 2nd p-p on CA; MSC 1.25x; Personal guarantee | AE26: Bajaj TL Sanction BFL/CL-MM/2025-26/JCL/01 dated 18-Aug-2025 | AF26: Floating; quarterly reset; WDV basis. 12-month moratorium. | AG26: =FALSE() -> FALSE
A27: 23 | B27: ICICI Bank | C27: Cash Credit | D27: FB | E27: Revolving | F27: =FALSE() -> FALSE | G27: =FALSE() -> FALSE | H27: 1 | I27: INR | J27: 50 | K27: =IFERROR(J27,0) -> 50 | M27: =IFERROR(IF(D27="FB-Term",IF(A27=RBL_TL_SNo,RBL_TL_PrincOS,IF(A27=YBL_TL_SNo,YBL_TL_PrincOS,IF(A27=Bajaj_TL_SNo,Bajaj_TL_PrincOS,0))),IF(L27<>"",L27,IF(UseFullUtil,K27,0))),0) -> 50 | N27: =IFERROR(M27/K27,0) -> 1 | O27: =IFERROR(K27-M27,0) -> 0 | P27: 6M I-MCLR (ICICI) | Q27: 0.0045 | R27: {=IFERROR(_xlfn.SWITCH(P27,"1Y MCLR (RBL Bank)",MCLR_RBL_1Y+Q27,"3M MCLR (YBL)",MCLR_YBL_3M+Q27,"6M I-MCLR (ICICI)",IMCLR_ICICI_6M+Q27,"12M MCLR (SIB)",MCLR_SIB_12M+Q27,"Bajaj Floating Reference Rate (BFRR)",BFRR_Bajaj+Q27,"Term SOFR (USD)",SOFR_3M+Q27,"3M T-Bill",TBill_3M+Q27,"Repo Rate",RepoRate+Q27,"FD rate",IFERROR(FD_Rate_RBL,0)+Q27,Q27),0)} -> 0.0875 | S27: Floating | T27: 0 | U27: On Demand | V27: 12 | W27: 0 | X27: 45916 | Y27: =IFERROR(EDATE(X27,T27),"") -> 45916 | Z27: =IFERROR(EDATE(X27,V27),"") -> 46281 | AA27: 45916 | AB27: 46268 | AC27: Working capital | AD27: 1st p-p on CA; 2nd p-p on FA; 2nd p-p mortgage Kalinga Nagar | AE27: ICICI Credit Arrangement Letter dated 16-Sep-2025 | AF27: Reset 6 monthly; one-way interchangeability CC→LC. | AG27: =FALSE() -> FALSE
A28: 24 | B28: ICICI Bank | C28: Working Capital Demand Loan (WCDL) | D28: FB | E28: Revolving | F28: =TRUE() -> TRUE | G28: =FALSE() -> FALSE | H28: 0 | I28: INR | J28: 50 | K28: =IFERROR(J28,0) -> 50 | M28: =IFERROR(IF(D28="FB-Term",IF(A28=RBL_TL_SNo,RBL_TL_PrincOS,IF(A28=YBL_TL_SNo,YBL_TL_PrincOS,IF(A28=Bajaj_TL_SNo,Bajaj_TL_PrincOS,0))),IF(L28<>"",L28,IF(UseFullUtil,K28,0))),0) -> 50 | N28: =IFERROR(M28/K28,0) -> 1 | O28: =IFERROR(K28-M28,0) -> 0 | P28: Repo Rate | Q28: 0 | R28: {=IFERROR(_xlfn.SWITCH(P28,"1Y MCLR (RBL Bank)",MCLR_RBL_1Y+Q28,"3M MCLR (YBL)",MCLR_YBL_3M+Q28,"6M I-MCLR (ICICI)",IMCLR_ICICI_6M+Q28,"12M MCLR (SIB)",MCLR_SIB_12M+Q28,"Bajaj Floating Reference Rate (BFRR)",BFRR_Bajaj+Q28,"Term SOFR (USD)",SOFR_3M+Q28,"3M T-Bill",TBill_3M+Q28,"Repo Rate",RepoRate+Q28,"FD rate",IFERROR(FD_Rate_RBL,0)+Q28,Q28),0)} -> 0.0525 | S28: Floating | T28: 0 | U28: On Maturity | V28: 3 | W28: 0 | X28: 45972 | Y28: =IFERROR(EDATE(X28,T28),"") -> 45972 | Z28: =IFERROR(EDATE(X28,V28),"") -> 46064 | AA28: 45972 | AB28: 46268 | AC28: Working capital (bullet) | AD28: 1st p-p on CA; 2nd p-p on FA; 2nd p-p mortgage Kalinga Nagar | AE28: ICICI WCDL Addendum dated 11-Nov-2025 | AF28: Repo reset; spread TBD. | AG28: =FALSE() -> FALSE
A29: 25 | B29: ICICI Bank | C29: Letter of Credit (Inland/Foreign) | D29: NFB | E29: Revolving | F29: =FALSE() -> FALSE | G29: =FALSE() -> FALSE | H29: 2 | I29: INR | J29: 150 | K29: =IFERROR(J29,0) -> 150 | M29: =IFERROR(IF(D29="FB-Term",IF(A29=RBL_TL_SNo,RBL_TL_PrincOS,IF(A29=YBL_TL_SNo,YBL_TL_PrincOS,IF(A29=Bajaj_TL_SNo,Bajaj_TL_PrincOS,0))),IF(L29<>"",L29,IF(UseFullUtil,K29,0))),0) -> 150 | N29: =IFERROR(M29/K29,0) -> 1 | O29: =IFERROR(K29-M29,0) -> 0 | P29: Fixed commission | Q29: 0.005 | R29: {=IFERROR(_xlfn.SWITCH(P29,"1Y MCLR (RBL Bank)",MCLR_RBL_1Y+Q29,"3M MCLR (YBL)",MCLR_YBL_3M+Q29,"6M I-MCLR (ICICI)",IMCLR_ICICI_6M+Q29,"12M MCLR (SIB)",MCLR_SIB_12M+Q29,"Bajaj Floating Reference Rate (BFRR)",BFRR_Bajaj+Q29,"Term SOFR (USD)",SOFR_3M+Q29,"3M T-Bill",TBill_3M+Q29,"Repo Rate",RepoRate+Q29,"FD rate",IFERROR(FD_Rate_RBL,0)+Q29,Q29),0)} -> 0.005 | S29: Fixed | T29: 0 | U29: On Maturity | V29: 5 | W29: 0 | X29: 45916 | Y29: =IFERROR(EDATE(X29,T29),"") -> 45916 | Z29: =IFERROR(EDATE(X29,V29),"") -> 46069 | AA29: 45916 | AB29: 46268 | AC29: RM, consumables, stores, spares, tools | AD29: 1st p-p on CA; 2nd p-p on FA; 2nd p-p mortgage Kalinga Nagar | AE29: ICICI Credit Arrangement Letter dated 16-Sep-2025 | AF29: LC to JSL Global Commodities Pte Ltd capped at INR 25 Cr. | AG29: =TRUE() -> TRUE
A30: 26 | B30: ICICI Bank | C30: SBLC for Buyers' Credit | D30: NFB | E30: Revolving | F30: =TRUE() -> TRUE | G30: =FALSE() -> FALSE | H30: 0 | I30: INR | J30: 150 | K30: =IFERROR(J30,0) -> 150 | M30: =IFERROR(IF(D30="FB-Term",IF(A30=RBL_TL_SNo,RBL_TL_PrincOS,IF(A30=YBL_TL_SNo,YBL_TL_PrincOS,IF(A30=Bajaj_TL_SNo,Bajaj_TL_PrincOS,0))),IF(L30<>"",L30,IF(UseFullUtil,K30,0))),0) -> 150 | N30: =IFERROR(M30/K30,0) -> 1 | O30: =IFERROR(K30-M30,0) -> 0 | P30: Fixed commission | Q30: 0.005 | R30: {=IFERROR(_xlfn.SWITCH(P30,"1Y MCLR (RBL Bank)",MCLR_RBL_1Y+Q30,"3M MCLR (YBL)",MCLR_YBL_3M+Q30,"6M I-MCLR (ICICI)",IMCLR_ICICI_6M+Q30,"12M MCLR (SIB)",MCLR_SIB_12M+Q30,"Bajaj Floating Reference Rate (BFRR)",BFRR_Bajaj+Q30,"Term SOFR (USD)",SOFR_3M+Q30,"3M T-Bill",TBill_3M+Q30,"Repo Rate",RepoRate+Q30,"FD rate",IFERROR(FD_Rate_RBL,0)+Q30,Q30),0)} -> 0.005 | S30: Fixed | T30: 0 | U30: On Maturity | V30: 5 | W30: 0 | X30: 45916 | Y30: =IFERROR(EDATE(X30,T30),"") -> 45916 | Z30: =IFERROR(EDATE(X30,V30),"") -> 46069 | AA30: 45916 | AB30: 46268 | AC30: Buyer's credit (USD/INR) | AD30: 1st p-p on CA; 2nd p-p on FA; 2nd p-p mortgage Kalinga Nagar | AE30: ICICI Credit Arrangement Letter dated 16-Sep-2025 | AF30: Sub-limit of LC. | AG30: =FALSE() -> FALSE
A31: 27 | B31: ICICI Bank | C31: Bank Guarantee - Performance | D31: NFB | E31: Revolving | F31: =TRUE() -> TRUE | G31: =FALSE() -> FALSE | H31: 0 | I31: INR | J31: 25 | K31: =IFERROR(J31,0) -> 25 | M31: =IFERROR(IF(D31="FB-Term",IF(A31=RBL_TL_SNo,RBL_TL_PrincOS,IF(A31=YBL_TL_SNo,YBL_TL_PrincOS,IF(A31=Bajaj_TL_SNo,Bajaj_TL_PrincOS,0))),IF(L31<>"",L31,IF(UseFullUtil,K31,0))),0) -> 25 | N31: =IFERROR(M31/K31,0) -> 1 | O31: =IFERROR(K31-M31,0) -> 0 | P31: Fixed commission | Q31: 0.005 | R31: {=IFERROR(_xlfn.SWITCH(P31,"1Y MCLR (RBL Bank)",MCLR_RBL_1Y+Q31,"3M MCLR (YBL)",MCLR_YBL_3M+Q31,"6M I-MCLR (ICICI)",IMCLR_ICICI_6M+Q31,"12M MCLR (SIB)",MCLR_SIB_12M+Q31,"Bajaj Floating Reference Rate (BFRR)",BFRR_Bajaj+Q31,"Term SOFR (USD)",SOFR_3M+Q31,"3M T-Bill",TBill_3M+Q31,"Repo Rate",RepoRate+Q31,"FD rate",IFERROR(FD_Rate_RBL,0)+Q31,Q31),0)} -> 0.005 | S31: Fixed | T31: 0 | U31: On Maturity | V31: 36 | W31: 0 | X31: 45916 | Y31: =IFERROR(EDATE(X31,T31),"") -> 45916 | Z31: =IFERROR(EDATE(X31,V31),"") -> 47012 | AA31: 45916 | AB31: 46268 | AC31: Bid bond, EMD, performance, customs | AD31: 1st p-p on CA; 2nd p-p on FA; 2nd p-p mortgage Kalinga Nagar | AE31: ICICI Credit Arrangement Letter dated 16-Sep-2025 | AF31: Sub-limit of LC. | AG31: =FALSE() -> FALSE
A32: 28 | B32: ICICI Bank | C32: Bank Guarantee - Financial | D32: NFB | E32: Revolving | F32: =TRUE() -> TRUE | G32: =FALSE() -> FALSE | H32: 0 | I32: INR | J32: 5 | K32: =IFERROR(J32,0) -> 5 | M32: =IFERROR(IF(D32="FB-Term",IF(A32=RBL_TL_SNo,RBL_TL_PrincOS,IF(A32=YBL_TL_SNo,YBL_TL_PrincOS,IF(A32=Bajaj_TL_SNo,Bajaj_TL_PrincOS,0))),IF(L32<>"",L32,IF(UseFullUtil,K32,0))),0) -> 5 | N32: =IFERROR(M32/K32,0) -> 1 | O32: =IFERROR(K32-M32,0) -> 0 | P32: Fixed commission | Q32: 0.006 | R32: {=IFERROR(_xlfn.SWITCH(P32,"1Y MCLR (RBL Bank)",MCLR_RBL_1Y+Q32,"3M MCLR (YBL)",MCLR_YBL_3M+Q32,"6M I-MCLR (ICICI)",IMCLR_ICICI_6M+Q32,"12M MCLR (SIB)",MCLR_SIB_12M+Q32,"Bajaj Floating Reference Rate (BFRR)",BFRR_Bajaj+Q32,"Term SOFR (USD)",SOFR_3M+Q32,"3M T-Bill",TBill_3M+Q32,"Repo Rate",RepoRate+Q32,"FD rate",IFERROR(FD_Rate_RBL,0)+Q32,Q32),0)} -> 0.006 | S32: Fixed | T32: 0 | U32: On Maturity | V32: 36 | W32: 0 | X32: 45916 | Y32: =IFERROR(EDATE(X32,T32),"") -> 45916 | Z32: =IFERROR(EDATE(X32,V32),"") -> 47012 | AA32: 45916 | AB32: 46268 | AC32: Financial guarantees | AD32: 1st p-p on CA; 2nd p-p on FA; 2nd p-p mortgage Kalinga Nagar | AE32: ICICI Credit Arrangement Letter dated 16-Sep-2025 | AF32: Sub-limit of LC. | AG32: =FALSE() -> FALSE
